Workbook

Sheet sheet1
A1: S.No | B1: USERNAME | C1: Caption | D1: Followers | E1: Hashtags | F1: Hashtag_count | G1: Time since posted | H1: Likes | I1: Like_rate | J1: Hours_Posted
A2: 24 | B2: astrokpj | C2: Was invited to speak at the annual Machine Learning conference on the role of Artificial Intelligence in big physics experiments such as LIGO. Much potential for astrophysics to collaborate with Tech giants Google, IBM and other large experiments at CERN. | D2: 3448 | E2: #artificialintelligence #machinelearning#bigdata #supercomputer #science#astrophysics #astronomy #einstein#relativity #theoryofrelativity #georgiatech#computerscience #blackhole #universe#cosmos | F2: =LEN(E2)-LEN(SUBSTITUTE(E2,"#","")) -> 15 | G2: 24 hours | H2: 349 | I2: =(H2/D2)*100 -> 10.12181 | J2: =VALUE(LEFT(G2,SEARCH(" ",G2)-1)) -> 24
A3: 17 | B3: gsmusicgroupllc | C3: gsmusicgroupllc#Repost @savageland32with @get_repost #SkrappdaGawd New Music on ALL Platforms | D3: 226 | E3: #youtube #applemusic #itunes#soundcloud #spinrilla #spotify #bigdata#blockchain #dontbandwagonlater | F3: =LEN(E3)-LEN(SUBSTITUTE(E3,"#","")) -> 9 | G3: 2 hours | H3: 350 | I3: =(H3/D3)*100 -> 154.86726 | J3: =VALUE(LEFT(G3,SEARCH(" ",G3)-1)) -> 2
A4: 24 | B4: lb3enterprises | C4: We’re only paid to move dirt once. It’s not just about excavating but placing it too. If fills aren’t properly planned for and executed, it can lead to moving material a second time which you don’t get paid for. That’s where good managers and operators who envision the final product are key. We’re hiring operators and grade checkers - send us an email at jobs@lb3enterprises.com to apply! | D4: 2039 | E4: #heavyequipment #underconstruction#dozer #realestate #bluecollar #D10#ibuildamerica #earthmover #caterpillar#demolition #mining #dumptruck #builtforit#truck #trucks #underconstruction#engineering #ironworker #construction#developer #dirt #constructionworker#safety #madeinamerica #excavator#civilengineering #quarry #Americanmade#development #operator | F4: =LEN(E4)-LEN(SUBSTITUTE(E4,"#","")) -> 30 | G4: 3 hours | H4: 351 | I4: =(H4/D4)*100 -> 17.214321 | J4: =VALUE(LEFT(G4,SEARCH(" ",G4)-1)) -> 3
A5: 26 | B5: superdatascience | C5: Live Population in Manhattan (hour-by-hour). Gif credit: @citrusvanilla . | D5: 966 | E5: #datascience #data #tech #technology#future #machinelearning #ai#visualizations #dataisbeautiful | F5: =LEN(E5)-LEN(SUBSTITUTE(E5,"#","")) -> 9 | G5: 5 hours | H5: 352 | I5: =(H5/D5)*100 -> 36.438923 | J5: =VALUE(LEFT(G5,SEARCH(" ",G5)-1)) -> 5
A6: 20 | B6: orcan_intel | C6: Global warming visualised. | D6: 2277 | E6: #data #bigdata #datavisualization#datascience #artificialintelligence | F6: =LEN(E6)-LEN(SUBSTITUTE(E6,"#","")) -> 5 | G6: 4 hours | H6: 353 | I6: =(H6/D6)*100 -> 15.502855 | J6: =VALUE(LEFT(G6,SEARCH(" ",G6)-1)) -> 4
A7: 5 | B7: theminest_ | C7: Instructions unclear... 🤔. Started building two speakers and ended up with two mining rigs 🤦‍♂️ | D7: 1618 | E7: #theminest #miningrig #gpumining#bitcoinmining #bitcoin #bitcoinmemes#cryptolife #cryptomemes #cryptomining#ethereum #litecoin #cryptonews #altcoins#hodl #hodlgang #investinyourself#blockchain #crypto #miningfarm#ethereummining #litecoinmining#bitcointrading #bitcoinexchange #bitcoins#coinbase | F7: =LEN(E7)-LEN(SUBSTITUTE(E7,"#","")) -> 25 | G7: 20 hours | H7: 354 | I7: =(H7/D7)*100 -> 21.878863 | J7: =VALUE(LEFT(G7,SEARCH(" ",G7)-1)) -> 20
A8: 1 | B8: mikequindazzi | C8: Who are #DataScientist and what do they do? >> @MikeQuindazzi >> #MachineLearning #AI #DataAnalytics #DataScienc #DataLake >> https://buff.ly/2kYmF0s | D8: 1600 | E8: #MachineLearning #AI #DataAnalytics #DataScienc #DataLake | F8: =LEN(E8)-LEN(SUBSTITUTE(E8,"#","")) -> 5 | G8: 11 hours | H8: 355 | I8: =(H8/D8)*100 -> 22.1875 | J8: =VALUE(LEFT(G8,SEARCH(" ",G8)-1)) -> 11
A9: 5 | B9: mikequindazzi | C9: 1 in 3 #Smartphones will ship w/ #MachineLearning and #ArtificialIntelligence at the chipset level by 2020 >> @MikeQuindazzi >> #IoT #AI 2018 Report >> https://buff.ly/2HV0VAQ | D9: 1600 | E9: #MachineLearning #artificialintelligence#AI #IoT | F9: =LEN(E9)-LEN(SUBSTITUTE(E9,"#","")) -> 4 | G9: 14 hours | H9: 356 | I9: =(H9/D9)*100 -> 22.25 | J9: =VALUE(LEFT(G9,SEARCH(" ",G9)-1)) -> 14
A10: 7 | B10: rare.planet | C10: Our most selling hand painted kettle!! Order this beautiful kettle now!! . | D10: 2573 | E10: #rareplanet #shopatrareplanet #India#indiangood #kolkata #calcutta#handpainted #homedecor #gifts#terracotta #kettles #product #likesforfollow #like4like #instalike#like4likeback #likes4tags | F10: =LEN(E10)-LEN(SUBSTITUTE(E10,"#","")) -> 17 | G10: 2 hours | H10: 357 | I10: =(H10/D10)*100 -> 13.874854 | J10: =VALUE(LEFT(G10,SEARCH(" ",G10)-1)) -> 2
A11: 25 | B11: palmariusdev | C11: Obtén tu tienda en línea ahora. | D11: 741 | E11: #marketing #programming#development #desarrollo #webdesign#diseñoweb #frontend #backend #apps#app #mobileapps #aplicaciones #españa#panama #argentina #chile #uruguay#digitalmarketing #socialmedia#ecommerce #tiendaonline #design#startup #emprender #website #paginaweb#followme #work #business #empresa | F11: =LEN(E11)-LEN(SUBSTITUTE(E11,"#","")) -> 30 | G11: 3 hours | H11: 358 | I11: =(H11/D11)*100 -> 48.31309 | J11: =VALUE(LEFT(G11,SEARCH(" ",G11)-1)) -> 3
A12: 15 | B12: artificialintelligence.a.i | C12: Tag him who promised to help you but he doesn't 😒.😂 | D12: 533 | E12: #artificialintelligence #ai#machinelearning#deeplearning #algorithm #algorithms #cs#ml #blockchain #sopia#robots #project#aiproject#tag#it#boats#artificialintelligenceai #github #data #python #R #coding#programming #coder #programmer | F12: =LEN(E12)-LEN(SUBSTITUTE(E12,"#","")) -> 25 | G12: 11 hours | H12: 94 | I12: =(H12/D12)*100 -> 17.636023 | J12: =VALUE(LEFT(G12,SEARCH(" ",G12)-1)) -> 11
A13: 21 | B13: bitpainting | C13: At 12 Noon EST today, BitPainting will be releasing a new work of rare #blockchain art! From Picasso to Van Gogh, build your iconic art collection on the #ethereum network! | D13: 835 | E13: #blockchain #ethereum | F13: =LEN(E13)-LEN(SUBSTITUTE(E13,"#","")) -> 2 | G13: 2 hours | H13: 93 | I13: =(H13/D13)*100 -> 11.137725 | J13: =VALUE(LEFT(G13,SEARCH(" ",G13)-1)) -> 2
... A33: 11 | B33: hollympeck | C33: Still on set. 🙃 Can't tell you what it's for! | D33: 273 | E33: #artificialintelligence | F33: =LEN(E33)-LEN(SUBSTITUTE(E33,"#","")) -> 1 | G33: 2 hours | H33: 41 | I33: =(H33/D33)*100 -> 15.018315 | J33: =VALUE(LEFT(G33,SEARCH(" ",G33)-1)) -> 2
A34: 17 | B34: remi_ole | D34: 2175 | E34: #entrepreneur #entrepreneurial#entrepreneurmindset #fametags#entrepreneurship #entrepreneurslife#entrepreneurs #entrepreneurquotes#entrepreneurlifestyle #business#businessowner #ceo #boss #top #high#rich #success #hustle #luxury #millionaire#billionaire #lifegoals #motivational #goals#grind #ambition #startup #mindset#achive #hardwork | F34: =LEN(E34)-LEN(SUBSTITUTE(E34,"#","")) -> 30 | G34: 2 hours | H34: 41 | I34: =(H34/D34)*100 -> 1.8850575 | J34: =VALUE(LEFT(G34,SEARCH(" ",G34)-1)) -> 2
A35: 19 | B35: greg_turner44 | C35: Join the international community of forex trading and change your financial situation with knowledge on binary and forex trading Grow your investment and smile tomorrow. With such an investment of $500 your guaranteed of making $4835 back as profit in a time frame of 14 days. This is no scam or joke, totally legitimate. DM me now for more info on my trading platform. | D35: 1003 | E35: #forex #rich #wealth #millionaire #invest#wallstreet #business #entrepreneurs#startup #startups #startuplife #technology#tech #digital #computer #gadget #gadgets#geek #geeks #media #newslol #books#reading #read #entrepreneurship#businessman #reader #marketingdigital#goodreads #seo | F35: =LEN(E35)-LEN(SUBSTITUTE(E35,"#","")) -> 30 | G35: 2 hours | H35: 40 | I35: =(H35/D35)*100 -> 3.9880359 | J35: =VALUE(LEFT(G35,SEARCH(" ",G35)-1)) -> 2
A36: 9 | B36: philosophercoin | C36: Isn't it funny to think that Bitcoin uses Artificial Scarcity to tackle inflation? - Follow me for more. | D36: 279 | E36: #Bitcoin #Cryptocurrency#Ethereum #stockmarket #currencytrading#digitalmarketing #litecoin #Currency #ico#token #mining #BitcoinExchange#Blockchain #money #community #crypto#CryptoExchange #fiat #forex #altcoin#stocks #profit #investor #investment#trader#forextrader #nyse #broker #forexnews#forexanalysis | F36: =LEN(E36)-LEN(SUBSTITUTE(E36,"#","")) -> 30 | G36: 2 hours | H36: 37 | I36: =(H36/D36)*100 -> 13.261649 | J36: =VALUE(LEFT(G36,SEARCH(" ",G36)-1)) -> 2
A37: 6 | B37: iamjaradwright | C37: Go get yours now! . | D37: 740 | E37: #product #moderndesign #concept#designing #designs #interiorarchitecture#designers #prototype #instadesign#menswear #ootdmen #lookoftheday#snobshots #streetwear #urbanfashion#fashiondiaries #menwithstreetstyle#menstyle #fashionkiller #fashiongram#weloveatl #whyiloveatl #discoveratl#atlantacollective #igersatlanta#atlantasnaps #dji #djimavic #dronestagram#drones | F37: =LEN(E37)-LEN(SUBSTITUTE(E37,"#","")) -> 30 | G37: 2 hours | H37: 35 | I37: =(H37/D37)*100 -> 4.7297297 | J37: =VALUE(LEFT(G37,SEARCH(" ",G37)-1)) -> 2
A38: 7 | B38: lenovoworkstations | C38: Check it out – we’re walking across the 🌎’s first #3DPrintedbridge w/ smart sensors for real-time data in #VR with #ThinkRevolutionist@MX3DBridge #NXTBLD . | D38: 259 | E38: .#Tech #virtualreality #IoT #Machinelearning | F38: =LEN(E38)-LEN(SUBSTITUTE(E38,"#","")) -> 4 | G38: 3 hours | H38: 35 | I38: =(H38/D38)*100 -> 13.513514 | J38: =VALUE(LEFT(G38,SEARCH(" ",G38)-1)) -> 3
A39: 24 | B39: writtorg | C39: "It is this perfect accuracy, this lack of play, of variety, that makes the machine-made article so lifeless." | D39: 2691 | E39: #newread #whattoread #summerreads#nowreading #readingislife #bookworm#booknerds #writt #writtorg #wellread#bookreco #bookrecommendations#whatareyoureading #igbooks #igreads#bookclub #bookalicious #classicliterature#classicbooks #bestquotes #quotes#goodreads #bookaddict #bookoftheday#quoteoftheday #machinelearning#machines #creativity #art | F39: =LEN(E39)-LEN(SUBSTITUTE(E39,"#","")) -> 29 | G39: 4 hours | H39: 34 | I39: =(H39/D39)*100 -> 1.2634708 | J39: =VALUE(LEFT(G39,SEARCH(" ",G39)-1)) -> 4
A40: 22 | B40: pazrahn | C40: The Peter McKinnon - Created this ridiculous mini cinema rig from left over camera gear. The inspiration came from YouTubers like Peter McKinnon so I named this rig after him. Perfect for filming coffee to making sweet low walking shots and epic selfie videos. | D40: 361 | E40: #pmbrollchallenge #Canon#Atomos #Panasonic #Movo #MovoVXR10#Sony #CanonLegriaMiniX #LegriaMiniX#Cine #Luts #Canada #SmallRig #product#moderndesign #concept #designing#designs #interiorarchitecture#magnumphotos #streetlife #documentary#exploreaustralia #australiagram#ilovesydney #canonphotos #canoneos | F40: =LEN(E40)-LEN(SUBSTITUTE(E40,"#","")) -> 27 | G40: 3 hours | H40: 33 | I40: =(H40/D40)*100 -> 9.1412742 | J40: =VALUE(LEFT(G40,SEARCH(" ",G40)-1)) -> 3
A41: 13 | B41: the_ios_developer | C41: 4K Ai | D41: 863 | E41: #developer #coding #programmer #javascript #programming #software #php#webdeveloper #computerscience #html #css #webdevelopment #java #coder #html5#webdev #backend #programmers #softwaredeveloper #softwareengineering #python#webdesign #frontend #development #css3 #wordpress #code #webdesigner #js | F41: =LEN(E41)-LEN(SUBSTITUTE(E41,"#","")) -> 29 | G41: 2 hours | H41: 32 | I41: =(H41/D41)*100 -> 3.7079954 | J41: =VALUE(LEFT(G41,SEARCH(" ",G41)-1)) -> 2
A42: 11 | B42: databowl | C42: Today we are featured in The Future CMO Magazine in @thetimes@raconteur_london Go get a copy! Read more here: https://www.raconteur.net/sponsored/how-to-use-machine-learning-the-right-way-tool-for-a-new-marketing-paradigm | D42: 149 | E42: #artificialintelligence #futurism#machinelearning #marketing#b2cmarketing #thetimes #thedrum#hubspot #leadgeneration | F42: =LEN(E42)-LEN(SUBSTITUTE(E42,"#","")) -> 9 | G42: 7 hours | H42: 31 | I42: =(H42/D42)*100 -> 20.805369 | J42: =VALUE(LEFT(G42,SEARCH(" ",G42)-1)) -> 7
A43: 14 | B43: entrancegmbh | C43: Greetings from #CEBIT2018#Pepper is getting ready for #afterwork#party #festival #tradefair maybe we get on #stage with #digitalism | D43: 122 | E43: #hannover #cebit#digitalisierung #entrancegmbh #wuppertal#startup #iot #AI #artificialintelligence | F43: =LEN(E43)-LEN(SUBSTITUTE(E43,"#","")) -> 9 | G43: 2 hours | H43: 31 | I43: =(H43/D43)*100 -> 25.409836 | J43: =VALUE(LEFT(G43,SEARCH(" ",G43)-1)) -> 2
A44: 17 | B44: illumensfragrance | C44: simple elegance from @mumzynotjess featuring Illumens ‘Poire 1796’ diffuser. We love seeing our products in your beautiful homes, thank you Jess | D44: 845 | E44: #repost #interiors#white #elegant #simple #minimal#poire1796 #scentyourhome#illumensfragrance #loveillumens#whiteblog #product #whiteinteriors #home | F44: =LEN(E44)-LEN(SUBSTITUTE(E44,"#","")) -> 14 | G44: 2 hours | H44: 31 | I44: =(H44/D44)*100 -> 3.6686391 | J44: =VALUE(LEFT(G44,SEARCH(" ",G44)-1)) -> 2
A45: 19 | B45: michaelgarza__ | C45: 328 S. Wetherly Drive, Beverly Hills, CA 90212. This beautiful new construction our team completed in early May 2018 was sold before the framing was even started!! I am kidding, but it sure felt that way! | D45: 614 | E45: #beverlyhills #realestate#losangelesrealestate #gc&management #standardoil #standardoilrealty#luxuryrealestate #luxurydesign#losangeles #designer #development#homes #interiordesign #hustle#luxurylifestyle | F45: =LEN(E45)-LEN(SUBSTITUTE(E45,"#","")) -> 15 | G45: 3 hours | H45: 31 | I45: =(H45/D45)*100 -> 5.0488599 | J45: =VALUE(LEFT(G45,SEARCH(" ",G45)-1)) -> 3
A46: 16 | B46: thebeautymindset | C46: Im limited edition 💁 -------------------------------📣 Donr forget to TURN ON notification ---- | D46: 151 | E46: thebeautymindset#businessman#quoteoftheday #businessowner#businesswoman #success #grind#motivation #motivational #lifestyle#happiness #entrepreneurs#entrepreneurlife #business #working #founder#startup #money #magazine #moneymaker#startuplife #successful #passion #inspiredaily#hardwork #hardworkpaysoff #desire | F46: =LEN(E46)-LEN(SUBSTITUTE(E46,"#","")) -> 26 | G46: 2 hours | H46: 31 | I46: =(H46/D46)*100 -> 20.529801 | J46: =VALUE(LEFT(G46,SEARCH(" ",G46)-1)) -> 2
... A49: 15 | B49: cryptocrackhead | C49: I officially spent the last of my tethers and available liquidity. All one can do now is be patient and remember why you bought Crypto in the first place. Mass adaption and bull run will follow shortly. Stay focused and blessed my fellow Cryptocrackhead's! Will be opening up our Telegram Group to the public soon, so stay tuned... the main event hasn't even begun yet. 😜🚀💰 | D49: 610 | E49: #cryptocrackhead#blockchain#cryptocurrency #crypto #decentralise#bitcoin #ethereum #ripple #dash#bitcoincash #monero #eos #cardano #tron#fiat #millionaire #trading #altcoins #money#future #biitcoinaire #gains #funny#currency #coinbase #freedom #binance#virtual #ai #coins | F49: =LEN(E49)-LEN(SUBSTITUTE(E49,"#","")) -> 30 | G49: 2 hours | H49: 30 | I49: =(H49/D49)*100 -> 4.9180328 | J49: =VALUE(LEFT(G49,SEARCH(" ",G49)-1)) -> 2
A50: 11 | B50: anandvanjape | D50: 460 | E50: #Designer #style #artist#brand #logo #monogram #corporate#identity #lifestyle #pure #luxury #product#posh #london #paris #milan #newyork#dubai #sydney #melbourne #mumbai#dublin #dubai #cosmetics #fashion #art#artdirector #creativity #creative #colour#abstract | F50: =LEN(E50)-LEN(SUBSTITUTE(E50,"#","")) -> 31 | G50: 2 hours | H50: 29 | I50: =(H50/D50)*100 -> 6.3043478 | J50: =VALUE(LEFT(G50,SEARCH(" ",G50)-1)) -> 2
A51: 10 | B51: brad_0611 | C51: Living in Texas is easy, even if your standards are high 😎💁‍♂️ // | D51: 1158 | E51: #frisco#dallas #dfw #texas #newconstruction#economy #development #landscaping#design #ivoteyes | F51: =LEN(E51)-LEN(SUBSTITUTE(E51,"#","")) -> 10 | G51: 2 hours | H51: 29 | I51: =(H51/D51)*100 -> 2.5043178 | J51: =VALUE(LEFT(G51,SEARCH(" ",G51)-1)) -> 2
A52: 21 | B52: eligible.api | C52: GG, you always have the best T-shirts! 🔥❄️💉 #codeblooded | D52: 285 | E52: #Eligible #EligibleAPI #HealthCare#HealthCareTech #HealthIT #engineering#Programming #Code #Software #API#HIPAA #AI #MachineLearning#DeepLearning #Tech #StartupLife#DataScience #security #Compliance | F52: =LEN(E52)-LEN(SUBSTITUTE(E52,"#","")) -> 19 | G52: 4 hours | H52: 29 | I52: =(H52/D52)*100 -> 10.175439 | J52: =VALUE(LEFT(G52,SEARCH(" ",G52)-1)) -> 4
A53: 14 | B53: magnodc | C53: Acción es la mejor arma 🌏🏰 | D53: 2014 | E53: #moneymaker #startup #entrepreneurlife#entrepreneurs #entrepreneurlifestyle#entrepreneurship #onlinemarketing#motivational #millionairemindset#successful #millionairelifestyle#businesswoman #inspiredaily#businessman #founder #businessowner#youngentrepreneur #startuplife #igersperu#discoverperu #sudamerica #ig_peru_#experienceperu #exploreperu #focalmarked #motivation #tbt #followme | F53: =LEN(E53)-LEN(SUBSTITUTE(E53,"#","")) -> 28 | G53: 2 hours | H53: 29 | I53: =(H53/D53)*100 -> 1.4399206 | J53: =VALUE(LEFT(G53,SEARCH(" ",G53)-1)) -> 2
A54: 18 | B54: ansonmccade | C54: Do you really need #blockchain? | D54: 2904 | E54: #blockchaintechnology #blockchains #tech#technology #IoT #InternetOfThings#Bitcoin #business #businessintelligence#BI #AI #ArtificialIntelligence #ML#MachineLearning #infographic #DL#DeepLearning #data #bigdata#datascience | F54: =LEN(E54)-LEN(SUBSTITUTE(E54,"#","")) -> 20 | G54: 3 hours | H54: 28 | I54: =(H54/D54)*100 -> 0.96418733 | J54: =VALUE(LEFT(G54,SEARCH(" ",G54)-1)) -> 3
A55: 12 | B55: mrproductionmiami | C55: “The picture that you took with your camera is the imagination you want to create with reality.”👍 💥Good weekend to everyone 😀 | D55: 140 | E55: #roamtheplanet #travelphotography#visualoflife #beachlife #dametraveler#artofvisuals #islandhopping#flashesofdelight #thecreative #product#moderndesign #concept #designing#designs #interiorarchitecture #designers#prototype #instadesign #designporn#innovation #igersmiami #miaexplore#miamiphotographer #ig_miami#roamflorida #lifestyle_miami #panasonic#lumix #panasoniclumix #gh5 | F55: =LEN(E55)-LEN(SUBSTITUTE(E55,"#","")) -> 30 | G55: 2 hours | H55: 28 | I55: =(H55/D55)*100 -> 20 | J55: =VALUE(LEFT(G55,SEARCH(" ",G55)-1)) -> 2
A56: 7 | B56: cris.nemeth | C56: All black & shiny ✨✨ | D56: 577 | E56: #allblackeverything #applewatch#applewatchseries3 #38mm #swarovski#pandora #weekendvibes #style #fashion#tech #startup | F56: =LEN(E56)-LEN(SUBSTITUTE(E56,"#","")) -> 11 | G56: 2 hours | H56: 27 | I56: =(H56/D56)*100 -> 4.6793761 | J56: =VALUE(LEFT(G56,SEARCH(" ",G56)-1)) -> 2
A57: 3 | B57: aitrading_official | C57: Alexander Barinov: 4 years as CFO in multinationals, over 10 years of experience as financial advisory in Deloitte & EY, 6 of them as a partner. Focused on strategic management, finance, legal, and compliance. Worked for the global corporations including publicly traded companies. 5 years experience in trading at NYSE and LSE exchanges. #whoiswho #aitrading #ai #aitradingteam#instateam #instapeople #ai #trading#artificialintelligence #crypto#cryptocurrency #blockchain #tradingforex#forex #fiatmoney #coins #machinelearning#userexperience #instamachinelearning#instabigdata #instamarketing#artificialintelligence #deeplearning#datascience #industry #marketing#bigdata #datascience #machinelearning#ml | D57: 255 | E57: #whoiswho #aitrading #ai #aitradingteam#instateam #instapeople #ai #trading#artificialintelligence #crypto#cryptocurrency #blockchain #tradingforex#forex #fiatmoney #coins #machinelearning#userexperience #instamachinelearning#instabigdata #instamarketing#artificialintelligence #deeplearning#datascience #industry #marketing#bigdata #datascience #machinelearning#ml | F57: =LEN(E57)-LEN(SUBSTITUTE(E57,"#","")) -> 30 | G57: 2 hours | H57: 25 | I57: =(H57/D57)*100 -> 9.8039216 | J57: =VALUE(LEFT(G57,SEARCH(" ",G57)-1)) -> 2
A58: 30 | B58: coding.is.life | C58: #Repost @wesabio Sometimes the truth hurts | | D58: 265 | E58: #Repost #Javascript #ReactJS #Ruby #GDPR #Graduation #Mobile#VueJS #JQuery #Developers #Programmers #JS #Gift #Dev #ArtificialIntelligence #MachineLearning #Linux#Humour #Humor #Fintech #API #Sysadmin #ML #WomenInTech #Ubuntu #Security#IIOT #Hackers #TechHumor | F58: =LEN(E58)-LEN(SUBSTITUTE(E58,"#","")) -> 29 | G58: 2 hours | H58: 25 | I58: =(H58/D58)*100 -> 9.4339623 | J58: =VALUE(LEFT(G58,SEARCH(" ",G58)-1)) -> 2
A59: 19 | B59: triatebr | C59: Imagine having access to the data of the air we breathe? | D59: 1766 | E59: #blockchain #tech #startups #projetos#linux #ethereum #programmer#InternetdasCoisas #smartcontract#internetofthings #technology #disruption#mobile #nodemcu #hyperledger #chain#programming #smartcontracts#hyperledgerfabric #artificialintelligence#iot #fintech #industry40 #cloud#mobilelegends #drones#personaldevelopment #healthy | F59: =LEN(E59)-LEN(SUBSTITUTE(E59,"#","")) -> 28 | G59: 4 hours | H59: 25 | I59: =(H59/D59)*100 -> 1.4156285 | J59: =VALUE(LEFT(G59,SEARCH(" ",G59)-1)) -> 4
A60: 22 | B60: _linda_smith567 | C60: Hello ......You could see the excitement in her face .....one of my client who just cash out and still willing to invest more.Dm me for your trading help | D60: 124 | E60: #любовь #gm #sme #smenigeria #profits#businessowners #businessplan#entrepreneurship #entrepreneur#blockchain #crypto #cointelegraph#bitcoinprice #mining #cryptocurrencies#bch #bitcoins #litecoin #investment#investor #stockmarket #stocks #getrich#makemoney #makemoneyonline#mentorship #mentoring #xrp #bitfinex#altcoins | F60: =LEN(E60)-LEN(SUBSTITUTE(E60,"#","")) -> 30 | G60: 2 hours | H60: 24 | I60: =(H60/D60)*100 -> 19.354839 | J60: =VALUE(LEFT(G60,SEARCH(" ",G60)-1)) -> 2
A61: 22 | B61: funnelaico | C61: Lead with the #AI advantage. | D61: 87 | E61: #AI #machinelearning #auto#realtors #tech#fitness #socialselling#artificialintelligence#local #sanantonio#realestate #socialmedia#business #sa#generator #car #innovation#cardealers#entrepreneurs #COO #app#sales #ML | F61: =LEN(E61)-LEN(SUBSTITUTE(E61,"#","")) -> 23 | G61: 4 hours | H61: 24 | I61: =(H61/D61)*100 -> 27.586207 | J61: =VALUE(LEFT(G61,SEARCH(" ",G61)-1)) -> 4
...

Sheet summary
A1: Total Posts | B1: Total Likes | C1: Average Likes | D1: Maximum Likes | E1: Average Followers | F1: Average Like Rate | G1: Average hashtag_count
A2: =COUNTA(sheet1!B:B)-1 -> 100 | B2: =SUM(sheet1!H:H) -> 6333 | C2: =AVERAGE(sheet1!H:H) -> 63.33 | D2: =MAX(sheet1!H:H) -> 358 | E2: =AVERAGE(sheet1!D:D) -> 961.96 | F2: =AVERAGE(sheet1!I:I) -> 15.160028 | G2: =AVERAGE(sheet1!F:F) -> 19.06

Sheet charts
A1: likes | B1: username | D1: Followers | E1: Likes | G1: Hashtag_count | H1: Likes
A2: 349 | B2: astrokpj | D2: 3448 | E2: 349 | G2: =SUM(E2:F2) -> 349 | H2: 349
A3: 350 | B3: gsmusicgroupllc | D3: 226 | E3: 350 | G3: =SUM(E3:F3) -> 350 | H3: 350
A4: 351 | B4: lb3enterprises | D4: 2039 | E4: 351 | G4: =SUM(E4:F4) -> 351 | H4: 351
A5: 352 | B5: superdatascience | D5: 966 | E5: 352 | G5: =SUM(E5:F5) -> 352 | H5: 352
A6: 353 | B6: orcan_intel | D6: 2277 | E6: 353 | G6: =SUM(E6:F6) -> 353 | H6: 353
A7: 354 | B7: theminest_ | D7: 1618 | E7: 354 | G7: =SUM(E7:F7) -> 354 | H7: 354
A8: 355 | B8: mikequindazzi | D8: 1600 | E8: 355 | G8: =SUM(E8:F8) -> 355 | H8: 355
A9: 356 | B9: mikequindazzi | D9: 1600 | E9: 356 | G9: =SUM(E9:F9) -> 356 | H9: 356
A10: 357 | B10: rare.planet | D10: 2573 | E10: 357 | G10: =SUM(E10:F10) -> 357 | H10: 357
A11: 358 | B11: palmariusdev | D11: 741 | E11: 358 | G11: =SUM(E11:F11) -> 358 | H11: 358
D12: 533 | E12: 94 | G12: =SUM(E12:F12) -> 94 | H12: 94
D13: 835 | E13: 93 | G13: =SUM(E13:F13) -> 93 | H13: 93
D14: 828 | E14: 90 | G14: =SUM(E14:F14) -> 90 | H14: 90
D15: 1433 | E15: 86 | G15: =SUM(E15:F15) -> 86 | H15: 86
D16: 914 | E16: 81 | G16: =SUM(E16:F16) -> 81 | H16: 81
D17: 1061 | E17: 80 | G17: =SUM(E17:F17) -> 80 | H17: 80
D18: 2785 | E18: 65 | G18: =SUM(E18:F18) -> 65 | H18: 65
D19: 631 | E19: 55 | G19: =SUM(E19:F19) -> 55 | H19: 55
D20: 971 | E20: 53 | G20: =SUM(E20:F20) -> 53 | H20: 53
D21: 3139 | E21: 51 | G21: =SUM(E21:F21) -> 51 | H21: 51
D22: 383 | E22: 50 | G22: =SUM(E22:F22) -> 50 | H22: 50
D23: 340 | E23: 49 | G23: =SUM(E23:F23) -> 49 | H23: 49
... D76: 371 | E76: 19 | G76: =SUM(E76:F76) -> 19 | H76: 19
D77: 334 | E77: 19 | G77: =SUM(#REF!) -> #REF! | H77: 19
D78: 1231 | E78: 18 | G78: =SUM(E78:F78) -> 18 | H78: 18
D79: 450 | E79: 18 | G79: =SUM(E79:F79) -> 18 | H79: 18
D80: 193 | E80: 18 | G80: =SUM(E80:F80) -> 18 | H80: 18
D81: 530 | E81: 17 | G81: =SUM(E81:F81) -> 17 | H81: 17
D82: 348 | E82: 17 | G82: =SUM(E82:F82) -> 17 | H82: 17
D83: 1196 | E83: 16 | G83: =SUM(E83:F83) -> 16 | H83: 16
D84: 66 | E84: 16 | G84: =SUM(E84:F84) -> 16 | H84: 16
D85: 118 | E85: 16 | G85: =SUM(E85:F85) -> 16 | H85: 16
D86: 145 | E86: 16 | G86: =SUM(E86:F86) -> 16 | H86: 16
D87: 91 | E87: 14 | G87: =SUM(E87:F87) -> 14 | H87: 14
D88: 894 | E88: 14 | G88: =SUM(E88:F88) -> 14 | H88: 14
D89: 1168 | E89: 13 | G89: =SUM(E89:F89) -> 13 | H89: 13
... D101: 105 | E101: 8 | G101: =SUM(E101:F101) -> 8 | H101: 8

Sheet Dashboard
D1: Instagram Engagement Analysis Dashboard
A5: Total Posts | B5: Total Likes | C5: Average Likes | D5: Maximum Likes | E5: Average Followers | F5: Average Like Rate | G5: Average hashtag_count
A6: =COUNTA(sheet1!B:B)-1 -> 100 | B6: =SUM(charts!H:H) -> 6333 | C6: =AVERAGE(charts!H:H) -> 63.33 | D6: =MAX(charts!H:H) -> 358 | E6: =AVERAGE(charts!D:D) -> 961.96 | F6: =AVERAGE(sheet1!I:I) -> 15.160028 | G6: =AVERAGE(sheet1!F:F) -> 19.06
